# try-catch-finally

```java
try {
  int a = 0;
  int b = 2 / a;
  System.out.println(a);
} catch (Exception e) {
  e.printStackTrace();
  System.out.println("in catch");
}
// out:
// in catch
```

执行到 `  int b = 2 / a;` 就中断了，直接进入 catch 代码块

```java
try {
    int a = 0;
    int b = 2 / a;
    System.out.println(a);
} catch (Exception e) {
    e.printStackTrace();
    System.out.println("in catch");
} finally {
    System.out.println("finally");
}
// out:
// in catch
// finally
```

不论是否有 exception，finally 必须执行。

补充：如果有返回值，返回值在 finally 里面改变，由于之前已经在内存里面缓存，返回的依然是缓存里面的，即 finally 改变无效



# throw 的中断

```java
private static int test() {
    for (int i = 0;; i++) {
        if (i == 100) {
            throw new RuntimeException("From loop");
            System.out.println("loop"); // 编译错误
        }
    }
}
```

以上代码输出语句编译无法通过

```
private static int test() {
    for (int i = 0;; i++) {
        if (i == 100) {
            try {
                throw new RuntimeException("From loop");
            } catch (Exception e) {
                e.printStackTrace();
            }
            System.out.println("loop");
            return 1;
        }
    }
}
```

异常被捕获，打印，能打印 loop，能返回

```
private static int test() {
    for (int i = 0; ; i++) {
        if (i == 100) {
            throw new RuntimeException("From loop");
        }
    }
}
```

可以直接跳出循环